Workbook

Sheet 設定
A1: 校種を選択してください。 | I1: 年度 | J1: 種別 | L1: 教育事務所 | M1: 市町村 | N1: 学校
A2: 小学校 | C2: =IF(A2="小学校","_tablesho",IF(A2="中学校","_tablechu","校種未選択")) -> _tablesho | I2: R08 | J2: Ks | L2: {=IF(A2="","校種未選択",_xlfn.UNIQUE(INDIRECT(C2&"[事務所名]")))} -> 盛岡 | M2: {=IF(A5="","教育事務所未選択",_xlfn.UNIQUE(_xlfn._xlws.FILTER(INDIRECT(C2&"[教育委員会名]"),INDIRECT(C2&"[事務所名]")=A5)))} -> 盛岡市 | N2: {=IF(A8="","市町村未選択",_xlfn.UNIQUE(_xlfn._xlws.FILTER(INDIRECT(C2&"["&C3&"]"),INDIRECT(C2&"[教育委員会名]")=A8)))} -> 盛岡市立仁王小学校
C3: =IF(A2="小学校","小学校名",IF(A2="中学校","中学校名","校種未選択")) -> 小学校名 | L3: 中部 | M3: 岩手町 | N3: 盛岡市立城南小学校
A4: 教育事務所を選択してください。 | J4: Ss | L4: 県南 | M4: 雫石町 | N4: 盛岡市立桜城小学校
A5: 盛岡 | J5: Sm | L5: 沿岸南部 | M5: 葛巻町 | N5: 盛岡市立厨川小学校
J6: Ks | L6: 宮古 | M6: 滝沢市 | N6: 盛岡市立仙北小学校
A7: 市町村を選択してください。 | J7: Km | L7: 県北 | M7: 紫波町 | N7: 盛岡市立杜陵小学校
A8: 盛岡市 | L8: 国独 | M8: 矢巾町 | N8: 盛岡市立山岸小学校
L9: 県立 | M9: 八幡平市 | N9: 盛岡市立大慈寺小学校
A10: 学校を選択してください。 | L10: その他 | N10: 盛岡市立米内小学校
A11: 盛岡市立仁王小学校 | N11: 盛岡市立土淵小学校
N12: 盛岡市立中野小学校
A13: 学校コード | N13: 盛岡市立本宮小学校
A14: {=IFERROR(IF(A11="","学校未選択",_xlfn.XLOOKUP(A11,INDIRECT(C2&"["&C3&"]"),INDIRECT(C2&"[コード番号]"))),"選択条件が変わっています。上から順に選び直してください。")} -> 110101 | N14: 盛岡市立青山小学校
N15: 盛岡市立北厨川小学校
N16: 盛岡市立河北小学校
N17: 盛岡市立上田小学校
N18: 盛岡市立山王小学校
N19: 盛岡市立緑が丘小学校
N20: 盛岡市立太田小学校
N21: 盛岡市立太田東小学校
N22: 盛岡市立城北小学校
N23: 盛岡市立大新小学校
N24: 盛岡市立松園小学校
N25: 盛岡市立月が丘小学校
N26: 盛岡市立高松小学校
... N43: 盛岡教育事務所

Sheet 名簿
A1: 表示例
A2: 通しNo | B2: 学校コード | C2: 数字 | D2: 記号2 | E2: 児童・生徒答案番号 | F2: 学年 | G2: 組 | H2: 番号 | I2: 氏名
A3: 1 | B3: 999999 | C3: 001 | D3: A | E3: =B3&C3&D3 -> 999999001A | F3: 1 | G3: 1 | H3: 1 | I3: 生徒１
E5: ↓自動表示（変更不可）
A6: 通しNo | B6: 学校コード | C6: 数字 | D6: 記号2 | E6: 児童・生徒答案番号 | F6: 学年 | G6: 組 | H6: 番号 | I6: 氏名
A7: 1 | B7: =設定!$A$14 -> 110101 | C7: 001 | D7: A | E7: =テーブル3[[#This Row],[学校コード]]&テーブル3[[#This Row],[数字]]&テーブル3[[#This Row],[記号2]] -> 110101001A | F7: 1 | G7: 1 | H7: 1 | I7: 生徒１
A8: 2 | B8: =設定!$A$14 -> 110101 | C8: 002 | D8: H | E8: =テーブル3[[#This Row],[学校コード]]&テーブル3[[#This Row],[数字]]&テーブル3[[#This Row],[記号2]] -> 110101002H | F8: 1 | G8: 1 | H8: 2 | I8: 生徒２
A9: 3 | B9: =設定!$A$14 -> 110101 | C9: 003 | D9: K | E9: =テーブル3[[#This Row],[学校コード]]&テーブル3[[#This Row],[数字]]&テーブル3[[#This Row],[記号2]] -> 110101003K | F9: 1 | G9: 2 | H9: 3 | I9: 生徒３
A10: 4 | B10: =設定!$A$14 -> 110101 | C10: 004 | D10: M | E10: =テーブル3[[#This Row],[学校コード]]&テーブル3[[#This Row],[数字]]&テーブル3[[#This Row],[記号2]] -> 110101004M | F10: 1 | G10: 2 | H10: 4 | I10: 生徒４
A11: 5 | B11: =設定!$A$14 -> 110101 | C11: 005 | D11: N | E11: =テーブル3[[#This Row],[学校コード]]&テーブル3[[#This Row],[数字]]&テーブル3[[#This Row],[記号2]] -> 110101005N | F11: 1 | G11: 2 | H11: 5 | I11: 生徒５
A12: 6 | B12: =設定!$A$14 -> 110101 | C12: 006 | D12: R | E12: =テーブル3[[#This Row],[学校コード]]&テーブル3[[#This Row],[数字]]&テーブル3[[#This Row],[記号2]] -> 110101006R | F12: 1 | G12: 2 | H12: 6 | I12: 生徒６
A13: 7 | B13: =設定!$A$14 -> 110101 | C13: 007 | D13: V | E13: =テーブル3[[#This Row],[学校コード]]&テーブル3[[#This Row],[数字]]&テーブル3[[#This Row],[記号2]] -> 110101007V | F13: 1 | G13: 2 | H13: 7 | I13: 生徒７
A14: 8 | B14: =設定!$A$14 -> 110101 | C14: 008 | D14: X | E14: =テーブル3[[#This Row],[学校コード]]&テーブル3[[#This Row],[数字]]&テーブル3[[#This Row],[記号2]] -> 110101008X | F14: 1 | G14: 2 | H14: 8 | I14: 生徒８
A15: 9 | B15: =設定!$A$14 -> 110101 | C15: 009 | D15: A | E15: =テーブル3[[#This Row],[学校コード]]&テーブル3[[#This Row],[数字]]&テーブル3[[#This Row],[記号2]] -> 110101009A | F15: 1 | G15: 2 | H15: 9 | I15: 生徒９
A16: 10 | B16: =設定!$A$14 -> 110101 | C16: 010 | D16: H | E16: =テーブル3[[#This Row],[学校コード]]&テーブル3[[#This Row],[数字]]&テーブル3[[#This Row],[記号2]] -> 110101010H | F16: 1 | G16: 2 | H16: 10 | I16: 生徒１０
A17: 11 | B17: =設定!$A$14 -> 110101 | C17: 011 | D17: K | E17: =テーブル3[[#This Row],[学校コード]]&テーブル3[[#This Row],[数字]]&テーブル3[[#This Row],[記号2]] -> 110101011K | F17: 1 | G17: 2 | H17: 11 | I17: 生徒１１
A18: 12 | B18: =設定!$A$14 -> 110101 | C18: 012 | D18: M | E18: =テーブル3[[#This Row],[学校コード]]&テーブル3[[#This Row],[数字]]&テーブル3[[#This Row],[記号2]] -> 110101012M | F18: 1 | G18: 2 | H18: 12 | I18: 生徒１２
... A26: 20 | B26: =設定!$A$14 -> 110101 | C26: 020 | D26: M | E26: =テーブル3[[#This Row],[学校コード]]&テーブル3[[#This Row],[数字]]&テーブル3[[#This Row],[記号2]] -> 110101020M | F26: 1 | G26: 2 | H26: 20 | I26: 生徒２０
A27: 21 | B27: =設定!$A$14 -> 110101 | C27: 021 | D27: N | E27: =テーブル3[[#This Row],[学校コード]]&テーブル3[[#This Row],[数字]]&テーブル3[[#This Row],[記号2]] -> 110101021N
A28: 22 | B28: =設定!$A$14 -> 110101 | C28: 022 | D28: R | E28: =テーブル3[[#This Row],[学校コード]]&テーブル3[[#This Row],[数字]]&テーブル3[[#This Row],[記号2]] -> 110101022R
A29: 23 | B29: =設定!$A$14 -> 110101 | C29: 023 | D29: V | E29: =テーブル3[[#This Row],[学校コード]]&テーブル3[[#This Row],[数字]]&テーブル3[[#This Row],[記号2]] -> 110101023V
A30: 24 | B30: =設定!$A$14 -> 110101 | C30: 024 | D30: X | E30: =テーブル3[[#This Row],[学校コード]]&テーブル3[[#This Row],[数字]]&テーブル3[[#This Row],[記号2]] -> 110101024X
A31: 25 | B31: =設定!$A$14 -> 110101 | C31: 025 | D31: A | E31: =テーブル3[[#This Row],[学校コード]]&テーブル3[[#This Row],[数字]]&テーブル3[[#This Row],[記号2]] -> 110101025A
A32: 26 | B32: =設定!$A$14 -> 110101 | C32: 026 | D32: H | E32: =テーブル3[[#This Row],[学校コード]]&テーブル3[[#This Row],[数字]]&テーブル3[[#This Row],[記号2]] -> 110101026H
A33: 27 | B33: =設定!$A$14 -> 110101 | C33: 027 | D33: K | E33: =テーブル3[[#This Row],[学校コード]]&テーブル3[[#This Row],[数字]]&テーブル3[[#This Row],[記号2]] -> 110101027K
A34: 28 | B34: =設定!$A$14 -> 110101 | C34: 028 | D34: M | E34: =テーブル3[[#This Row],[学校コード]]&テーブル3[[#This Row],[数字]]&テーブル3[[#This Row],[記号2]] -> 110101028M
A35: 29 | B35: =設定!$A$14 -> 110101 | C35: 029 | D35: N | E35: =テーブル3[[#This Row],[学校コード]]&テーブル3[[#This Row],[数字]]&テーブル3[[#This Row],[記号2]] -> 110101029N
A36: 30 | B36: =設定!$A$14 -> 110101 | C36: 030 | D36: R | E36: =テーブル3[[#This Row],[学校コード]]&テーブル3[[#This Row],[数字]]&テーブル3[[#This Row],[記号2]] -> 110101030R
A37: 31 | B37: =設定!$A$14 -> 110101 | C37: 031 | D37: V | E37: =テーブル3[[#This Row],[学校コード]]&テーブル3[[#This Row],[数字]]&テーブル3[[#This Row],[記号2]] -> 110101031V
A38: 32 | B38: =設定!$A$14 -> 110101 | C38: 032 | D38: X | E38: =テーブル3[[#This Row],[学校コード]]&テーブル3[[#This Row],[数字]]&テーブル3[[#This Row],[記号2]] -> 110101032X
... A326: 320 | B326: =設定!$A$14 -> 110101 | C326: 320 | D326: X | E326: =テーブル3[[#This Row],[学校コード]]&テーブル3[[#This Row],[数字]]&テーブル3[[#This Row],[記号2]] -> 110101320X

Sheet 小学校コード一覧表
A1: 学校コード一覧表 | D1: 46085
A2: コード番号 | B2: 事務所名 | C2: 教育委員会名 | D2: 小学校名
A3: 110101 | B3: 盛岡 | C3: 盛岡市 | D3: 盛岡市立仁王小学校
A4: 110102 | B4: 盛岡 | C4: 盛岡市 | D4: 盛岡市立城南小学校
A5: 110103 | B5: 盛岡 | C5: 盛岡市 | D5: 盛岡市立桜城小学校
A6: 110104 | B6: 盛岡 | C6: 盛岡市 | D6: 盛岡市立厨川小学校
A7: 110105 | B7: 盛岡 | C7: 盛岡市 | D7: 盛岡市立仙北小学校
A8: 110106 | B8: 盛岡 | C8: 盛岡市 | D8: 盛岡市立杜陵小学校
A9: 110107 | B9: 盛岡 | C9: 盛岡市 | D9: 盛岡市立山岸小学校
A10: 110108 | B10: 盛岡 | C10: 盛岡市 | D10: 盛岡市立大慈寺小学校
A11: 110109 | B11: 盛岡 | C11: 盛岡市 | D11: 盛岡市立米内小学校
A12: 110110 | B12: 盛岡 | C12: 盛岡市 | D12: 盛岡市立土淵小学校
A13: 110111 | B13: 盛岡 | C13: 盛岡市 | D13: 盛岡市立中野小学校
A14: 110112 | B14: 盛岡 | C14: 盛岡市 | D14: 盛岡市立本宮小学校
... A37: 110138 | B37: 盛岡 | C37: 盛岡市 | D37: 盛岡市立都南東小学校
A38: 110139 | B38: 盛岡 | C38: 盛岡市 | D38: 盛岡市立北松園小学校 | E38: R8玉山小と統合
A39: 110140 | B39: 盛岡 | C39: 盛岡市 | D39: 盛岡市立玉山小学校 | E39: R8廃止
A40: 110143 | B40: 盛岡 | C40: 盛岡市 | D40: 盛岡市立渋民小学校
A41: 110145 | B41: 盛岡 | C41: 盛岡市 | D41: 盛岡市立巻堀小学校
A42: 110146 | B42: 盛岡 | C42: 盛岡市 | D42: 盛岡市立好摩小学校
A43: 110201 | B43: 盛岡 | C43: 岩手町 | D43: 岩手町立沼宮内小学校
A44: 110202 | B44: 盛岡 | C44: 岩手町 | D44: 岩手町立川口小学校
A45: 110204 | B45: 盛岡 | C45: 岩手町 | D45: 岩手町立一方井小学校
A46: 110301 | B46: 盛岡 | C46: 雫石町 | D46: 雫石町立雫石小学校
A47: 110302 | B47: 盛岡 | C47: 雫石町 | D47: 雫石町立七ツ森小学校
A48: 110304 | B48: 盛岡 | C48: 雫石町 | D48: 雫石町立西山小学校
A49: 110306 | B49: 盛岡 | C49: 雫石町 | D49: 雫石町立御明神小学校
A50: 110308 | B50: 盛岡 | C50: 雫石町 | D50: 雫石町立御所小学校
A51: 110401 | B51: 盛岡 | C51: 葛巻町 | D51: 葛巻町立葛巻小学校
... A205: 152302 | B205: 宮古 | C205: 宮古市 | D205: 宮古市立鍬ケ崎小学校
A206: 152304 | B206: 宮古 | C206: 宮古市 | D206: 宮古市立磯鶏小学校 | E206: R8高浜小と統合
A207: 152305 | B207: 宮古 | C207: 宮古市 | D207: 宮古市立山口小学校
A208: 152306 | B208: 宮古 | C208: 宮古市 | D208: 宮古市立千徳小学校
A209: 152307 | B209: 宮古 | C209: 宮古市 | D209: 宮古市立高浜小学校 | E209: R8廃止
A210: 152309 | B210: 宮古 | C210: 宮古市 | D210: 宮古市立花輪小学校
A211: 152310 | B211: 宮古 | C211: 宮古市 | D211: 宮古市立津軽石小学校
A212: 152312 | B212: 宮古 | C212: 宮古市 | D212: 宮古市立重茂小学校
A213: 152315 | B213: 宮古 | C213: 宮古市 | D213: 宮古市立崎山小学校
A214: 152316 | B214: 宮古 | C214: 宮古市 | D214: 宮古市立田老第一小学校
A215: 152318 | B215: 宮古 | C215: 宮古市 | D215: 宮古市立新里小学校
...

Sheet 中学校コード一覧表
A1: 学校コード一覧表 | D1: =小学校コード一覧表!D1 -> 46085
A2: コード番号 | B2: 事務所名 | C2: 教育委員会名 | D2: 中学校名
A3: 210101 | B3: 盛岡 | C3: 盛岡市 | D3: 盛岡市立下橋中学校
A4: 210102 | B4: 盛岡 | C4: 盛岡市 | D4: 盛岡市立下小路中学校
A5: 210103 | B5: 盛岡 | C5: 盛岡市 | D5: 盛岡市立厨川中学校
A6: 210104 | B6: 盛岡 | C6: 盛岡市 | D6: 盛岡市立上田中学校
A7: 210105 | B7: 盛岡 | C7: 盛岡市 | D7: 盛岡市立河南中学校
A8: 210106 | B8: 盛岡 | C8: 盛岡市 | D8: 盛岡市立仙北中学校
A9: 210107 | B9: 盛岡 | C9: 盛岡市 | D9: 盛岡市立大宮中学校
A10: 210108 | B10: 盛岡 | C10: 盛岡市 | D10: 盛岡市立米内中学校
A11: 210109 | B11: 盛岡 | C11: 盛岡市 | D11: 盛岡市立土淵中学校
A12: 210110 | B12: 盛岡 | C12: 盛岡市 | D12: 盛岡市立黒石野中学校
A13: 210112 | B13: 盛岡 | C13: 盛岡市 | D13: 盛岡市立城西中学校
A14: 210113 | B14: 盛岡 | C14: 盛岡市 | D14: 盛岡市立城東中学校
... A20: 210119 | B20: 盛岡 | C20: 盛岡市 | D20: 盛岡市立見前南中学校
A21: 210120 | B21: 盛岡 | C21: 盛岡市 | D21: 盛岡市立北松園中学校 | E21: R8玉山中と統合
A22: 210121 | B22: 盛岡 | C22: 盛岡市 | D22: 盛岡市立玉山中学校 | E22: R8廃止
A23: 210123 | B23: 盛岡 | C23: 盛岡市 | D23: 盛岡市立渋民中学校
A24: 210124 | B24: 盛岡 | C24: 盛岡市 | D24: 盛岡市立巻堀中学校
A25: 210125 | B25: 盛岡 | C25: 盛岡市 | D25: 盛岡市立黒石野中学校北杜分校
A26: 210201 | B26: 盛岡 | C26: 岩手町 | D26: 岩手町立沼宮内中学校
A27: 210202 | B27: 盛岡 | C27: 岩手町 | D27: 岩手町立川口中学校
A28: 210204 | B28: 盛岡 | C28: 岩手町 | D28: 岩手町立一方井中学校
A29: 210301 | B29: 盛岡 | C29: 雫石町 | D29: 雫石町立雫石中学校
A30: 210401 | B30: 盛岡 | C30: 葛巻町 | D30: 葛巻町立葛巻中学校
A31: 210402 | B31: 盛岡 | C31: 葛巻町 | D31: 葛巻町立小屋瀬中学校
A32: 210403 | B32: 盛岡 | C32: 葛巻町 | D32: 葛巻町立江刈中学校
A33: 210501 | B33: 盛岡 | C33: 滝沢市 | D33: 滝沢市立滝沢南中学校
A34: 210502 | B34: 盛岡 | C34: 滝沢市 | D34: 滝沢市立滝沢中学校
... A62: 221101 | B62: 中部 | C62: 北上市 | D62: 北上市立上野中学校
A63: 221102 | B63: 中部 | C63: 北上市 | D63: 北上市立北上中学校 | E63: R8東陵中と統合
A64: 221103 | B64: 中部 | C64: 北上市 | D64: 北上市立東陵中学校 | E64: R8廃止
A65: 221104 | B65: 中部 | C65: 北上市 | D65: 北上市立飯豊中学校
A66: 221105 | B66: 中部 | C66: 北上市 | D66: 北上市立北上北中学校
A67: 221106 | B67: 中部 | C67: 北上市 | D67: 北上市立南中学校
A68: 221107 | B68: 中部 | C68: 北上市 | D68: 北上市立江釣子中学校
A69: 221108 | B69: 中部 | C69: 北上市 | D69: 北上市立和賀西中学校
A70: 221109 | B70: 中部 | C70: 北上市 | D70: 北上市立和賀東中学校
A71: 221201 | B71: 中部 | C71: 西和賀町 | D71: 西和賀町立湯田中学校
A72: 221202 | B72: 中部 | C72: 西和賀町 | D72: 西和賀町立沢内中学校
...
